2023-09-07 13:22:16,922 INFO Bot: PsyTetrica [@Psytet_bot]
2023-09-07 13:22:16,922 INFO Start polling.
2023-09-07 13:54:56,538 ERROR Cause exception while getting updates.
Traceback (most recent call last):
  File "/usr/local/lib/python3.10/dist-packages/aiogram/dispatcher/dispatcher.py", line 381, in start_polling
    updates = await self.bot.get_updates(
  File "/usr/local/lib/python3.10/dist-packages/aiogram/bot/bot.py", line 110, in get_updates
    result = await self.request(api.Methods.GET_UPDATES, payload)
  File "/usr/local/lib/python3.10/dist-packages/aiogram/bot/base.py", line 236, in request
    return await api.make_request(await self.get_session(), self.server, self.__token, method, data, files,
  File "/usr/local/lib/python3.10/dist-packages/aiogram/bot/api.py", line 140, in make_request
    return check_result(method, response.content_type, response.status, await response.text())
  File "/usr/local/lib/python3.10/dist-packages/aiogram/bot/api.py", line 128, in check_result
    raise exceptions.TelegramAPIError(description)
aiogram.utils.exceptions.TelegramAPIError: Bad Gateway
2023-09-07 14:50:01,139 ERROR Task exception was never retrieved
future: <Task finished name='Task-376' coro=<Dispatcher._process_polling_updates() done, defined at /usr/local/lib/python3.10/dist-packages/aiogram/dispatcher/dispatcher.py:407> exception=MessageToDeleteNotFound('Message to delete not found')>
Traceback (most recent call last):
  File "/usr/local/lib/python3.10/dist-packages/aiogram/dispatcher/dispatcher.py", line 415, in _process_polling_updates
    for responses in itertools.chain.from_iterable(await self.process_updates(updates, fast)):
  File "/usr/local/lib/python3.10/dist-packages/aiogram/dispatcher/dispatcher.py", line 235, in process_updates
    return await asyncio.gather(*tasks)
  File "/usr/local/lib/python3.10/dist-packages/aiogram/dispatcher/handler.py", line 117, in notify
    response = await handler_obj.handler(*args, **partial_data)
  File "/usr/local/lib/python3.10/dist-packages/aiogram/dispatcher/dispatcher.py", line 256, in process_update
    return await self.message_handlers.notify(update.message)
  File "/usr/local/lib/python3.10/dist-packages/aiogram/dispatcher/handler.py", line 117, in notify
    response = await handler_obj.handler(*args, **partial_data)
  File "/home/bot/PsyTetricaBot/bot.py", line 1313, in text
    await msg.delete()
  File "/usr/local/lib/python3.10/dist-packages/aiogram/types/message.py", line 3096, in delete
    return await self.bot.delete_message(self.chat.id, self.message_id)
  File "/usr/local/lib/python3.10/dist-packages/aiogram/bot/bot.py", line 3300, in delete_message
    return await self.request(api.Methods.DELETE_MESSAGE, payload)
  File "/usr/local/lib/python3.10/dist-packages/aiogram/bot/base.py", line 236, in request
    return await api.make_request(await self.get_session(), self.server, self.__token, method, data, files,
  File "/usr/local/lib/python3.10/dist-packages/aiogram/bot/api.py", line 140, in make_request
    return check_result(method, response.content_type, response.status, await response.text())
  File "/usr/local/lib/python3.10/dist-packages/aiogram/bot/api.py", line 115, in check_result
    exceptions.BadRequest.detect(description)
  File "/usr/local/lib/python3.10/dist-packages/aiogram/utils/exceptions.py", line 140, in detect
    raise err(cls.text or description)
aiogram.utils.exceptions.MessageToDeleteNotFound: Message to delete not found
2023-09-07 14:50:07,431 ERROR Task exception was never retrieved
future: <Task finished name='Task-387' coro=<Dispatcher._process_polling_updates() done, defined at /usr/local/lib/python3.10/dist-packages/aiogram/dispatcher/dispatcher.py:407> exception=MessageToDeleteNotFound('Message to delete not found')>
Traceback (most recent call last):
  File "/usr/local/lib/python3.10/dist-packages/aiogram/dispatcher/dispatcher.py", line 415, in _process_polling_updates
    for responses in itertools.chain.from_iterable(await self.process_updates(updates, fast)):
  File "/usr/local/lib/python3.10/dist-packages/aiogram/dispatcher/dispatcher.py", line 235, in process_updates
    return await asyncio.gather(*tasks)
  File "/usr/local/lib/python3.10/dist-packages/aiogram/dispatcher/handler.py", line 117, in notify
    response = await handler_obj.handler(*args, **partial_data)
  File "/usr/local/lib/python3.10/dist-packages/aiogram/dispatcher/dispatcher.py", line 256, in process_update
    return await self.message_handlers.notify(update.message)
  File "/usr/local/lib/python3.10/dist-packages/aiogram/dispatcher/handler.py", line 117, in notify
    response = await handler_obj.handler(*args, **partial_data)
  File "/home/bot/PsyTetricaBot/bot.py", line 1321, in text
    await msg.delete()
  File "/usr/local/lib/python3.10/dist-packages/aiogram/types/message.py", line 3096, in delete
    return await self.bot.delete_message(self.chat.id, self.message_id)
  File "/usr/local/lib/python3.10/dist-packages/aiogram/bot/bot.py", line 3300, in delete_message
    return await self.request(api.Methods.DELETE_MESSAGE, payload)
  File "/usr/local/lib/python3.10/dist-packages/aiogram/bot/base.py", line 236, in request
    return await api.make_request(await self.get_session(), self.server, self.__token, method, data, files,
  File "/usr/local/lib/python3.10/dist-packages/aiogram/bot/api.py", line 140, in make_request
    return check_result(method, response.content_type, response.status, await response.text())
  File "/usr/local/lib/python3.10/dist-packages/aiogram/bot/api.py", line 115, in check_result
    exceptions.BadRequest.detect(description)
  File "/usr/local/lib/python3.10/dist-packages/aiogram/utils/exceptions.py", line 140, in detect
    raise err(cls.text or description)
aiogram.utils.exceptions.MessageToDeleteNotFound: Message to delete not found
